<?xml version="1.0"?>
<robot xmlns:xacro="http://www.ros.org/wiki/xacro">

<xacro:include filename="inertia_macros.xacro"/>
    <material name="white">
        <color rgba="1 1 1 1"/>
    </material>

    <material name="orange">
        <color rgba="1 0.3 0.1 1"/>
    </material>

    <material name="blue">
        <color rgba="0.2 0.2 1 1"/>
    </material>

    <material name="black">
        <color rgba="0 0 0 1"/>
    </material>

    <link name="base_link">

    </link>

    <joint name="chassis_joint" type="fixed">
        <parent link="base_link"/>
        <child link="chassis"/>
        <origin xyz="-0.1 0 0"/>
    </joint>

    <link name="chassis">
        <visual>
            <origin xyz="0.15 0 0.075" rpy="0 0 0"/>
            <geometry>
                <box size="1.2 0.6 0.26"/>
            </geometry>
            <material name="white"/>
        </visual>
        <collision>
            <origin xyz="0.15 0 0.075" rpy="0 0 0"/>
            <geometry>
                <box size="1.2 0.6 0.26"/>
            </geometry>
        </collision>
        <xacro:inertial_box mass="0.5" x="1.2" y="0.6" z="0.26">
            <origin xyz="0.15 0 0.075" rpy="0 0 0"/>
        </xacro:inertial_box>
    </link>

    <gazebo reference="chassis">
        <material>Gazebo/White</material>
    </gazebo>
    
    <!-- LEFT WHEEL -->

    <joint name="left_wheel_joint" type="continuous">
        <parent link="base_link"/>
        <child link="left_wheel"/>
        <origin xyz="-0.38 0.38 0" rpy="-${pi/2} 0 0"/>
        <axis xyz="0 0 1"/>
    </joint>

    <link name="left_wheel">
        <visual>
            <geometry>
                <cylinder length="0.15" radius="0.17"/>
            </geometry>
            <material name="blue"/>
        </visual>
        <collision>
            <geometry>
                <cylinder radius="0.17" length="0.15"/>
            </geometry>
        </collision>
        <xacro:inertial_cylinder mass="0.1" length="0.15" radius="0.17">
            <origin xyz="0 0 0" rpy="0 0 0"/>
        </xacro:inertial_cylinder>
    </link>

    <gazebo reference="left_wheel">
        <material>Gazebo/Blue</material>
        <mu1 value="10.0"/>
        <mu2 value="10.0"/>
        <kp value="10000000.0" />
        <kd value="1.0" />
    </gazebo>
 
    <!-- RIGHT WHEEL -->

    <joint name="right_wheel_joint" type="continuous">
        <parent link="base_link"/>
        <child link="right_wheel"/>
        <origin xyz="-0.38 -0.38 0" rpy="${pi/2} 0 0"/>
        <axis xyz="0 0 -1"/>
    </joint>

    <link name="right_wheel">
        <visual>
            <geometry>
                <cylinder length="0.15" radius="0.17"/>
            </geometry>
            <material name="blue"/>
        </visual>
        <collision>
            <geometry>
                <cylinder radius="0.17" length="0.15"/>
            </geometry>
        </collision>
        <xacro:inertial_cylinder mass="0.1" length="0.15" radius="0.17">
            <origin xyz="0 0 0" rpy="0 0 0"/>
        </xacro:inertial_cylinder>
    </link>

    <gazebo reference="right_wheel">
        <material>Gazebo/Blue</material>
        <mu1 value="10.0"/>
        <mu2 value="10.0"/>
        <kp value="10000000.0" />
        <kd value="1.0" />
    </gazebo>

    <!-- BACK LEFT WHEEL -->

    <joint name="back_left_wheel_joint" type="continuous">
        <parent link="base_link"/>
        <child link="back_left_wheel"/>
        <origin xyz="0.38 0.38 0" rpy="-${pi/2} 0 0"/>
        <axis xyz="0 0 1"/>
    </joint>

    <link name="back_left_wheel">
        <visual>
            <geometry>
                <cylinder length="0.15" radius="0.17"/>
            </geometry>
            <material name="blue"/>
        </visual>
        <collision>
            <geometry>
                <cylinder radius="0.17" length="0.15"/>
            </geometry>
        </collision>
        <xacro:inertial_cylinder mass="0.1" length="0.15" radius="0.17">
            <origin xyz="0 0 0" rpy="0 0 0"/>
        </xacro:inertial_cylinder>
    </link>

    <gazebo reference="back_left_wheel">
        <material>Gazebo/Blue</material>
        <mu1 value="10.0"/>
        <mu2 value="10.0"/>
        <kp value="10000000.0" />
        <kd value="1.0" />
    </gazebo>

    <!-- BACK RIGHT WHEEL -->

    <joint name="back_right_wheel_joint" type="continuous">
        <parent link="base_link"/>
        <child link="back_right_wheel"/>
        <origin xyz="0.38 -0.38 0" rpy="${pi/2} 0 0"/>
        <axis xyz="0 0 -1"/>
    </joint>

    <link name="back_right_wheel">
        <visual>
            <geometry>
                <cylinder length="0.15" radius="0.17"/>
            </geometry>
            <material name="blue"/>
        </visual>
        <collision>
            <geometry>
                <cylinder radius="0.17" length="0.15"/>
            </geometry>
        </collision>
        <xacro:inertial_cylinder mass="0.1" length="0.15" radius="0.17">
            <origin xyz="0 0 0" rpy="0 0 0"/>
        </xacro:inertial_cylinder>
    </link>

    <gazebo reference="back_right_wheel">
        <material>Gazebo/Blue</material>
        <mu1 value="10.0"/>
        <mu2 value="10.0"/>
        <kp value="10000000.0" />
        <kd value="1.0" />
    </gazebo>

</robot>
